Workbook

Sheet Main
E1: الراتب السابق | F1: الزيادة السنوية | G1: الراتب بعد الزيادة السنوية | N1: الراتب السابق | O1: الزيادة السنوية | P1: الراتب بعد الزيادة السنوية | W1: الراتب السابق | X1: الزيادة السنوية | Y1: الراتب بعد الزيادة السنوية | AF1: الراتب السابق | AG1: الزيادة السنوية | AH1: الراتب بعد الزيادة السنوية
E2: 1500 | F2: 0.15 | G2: =SUM(E2+(E2*F2)) -> 1725 | N2: 1500 | O2: 0.15 | P2: =SUM(N2+(N2*O2)) -> 1725 | W2: 1500 | X2: 0.15 | Y2: =SUM(W2+(W2*X2)) -> 1725 | AF2: 1500 | AG2: 0.15 | AH2: =SUM(AF2+(AF2*AG2)) -> 1725
D3: الراتب الحالي | E3: فئة اليوم | F3: ريد الأجازات | G3: ايام الاجازات | H3: المتبقي | M3: الراتب الحالي | N3: فئة اليوم | O3: ريد الأجازات | P3: ايام الاجازات | Q3: المتبقي | V3: الراتب الحالي | W3: فئة اليوم | X3: ريد الأجازات | Y3: ايام الاجازات | Z3: المتبقي | AE3: الراتب الحالي | AF3: فئة اليوم | AG3: ريد الأجازات | AH3: ايام الاجازات | AI3: المتبقي
D4: =SUM(G2) -> 1725 | E4: =SUM(D4/30) -> 57.5 | F4: 30 | G4: =SUM(C15:I15,C22:I22,C36:I36) -> 0 | H4: =SUM(F4-G4) -> 30 | M4: =SUM(P2) -> 1725 | N4: =SUM(M4/30) -> 57.5 | O4: 30 | P4: =SUM(L15:R15,L22:R22,L36:R36) -> 0 | Q4: =SUM(O4-P4) -> 30 | V4: =SUM(Y2) -> 1725 | W4: =SUM(V4/30) -> 57.5 | X4: 30 | Y4: =SUM(U15:AA15,U22:AA22,U36:AA36) -> 0 | Z4: =SUM(X4-Y4) -> 30 | AE4: =SUM(AH2) -> 1725 | AF4: =SUM(AE4/30) -> 57.5 | AG4: 30 | AH4: =SUM(AD15:AJ15,AD22:AJ22,AD36:AJ36) -> 0 | AI4: =SUM(AG4-AH4) -> 30
B7: يناير | K7: فبراير | T7: مارس | AC7: مارس
B9: الراتب | C9: الراتب + مكافأة | D9: أيام الإضافي | E9: حساب الإضافي | F9: إجمالي أيام العمل | G9: راتب أيام العمل | H9: السهرات | I9: الأساسي | K9: الراتب | L9: الراتب + مكافأة | M9: أيام الإضافي | N9: حساب الإضافي | O9: إجمالي أيام العمل | P9: راتب أيام العمل | Q9: السهرات | R9: الأساسي | T9: الراتب | U9: الراتب + مكافأة | V9: أيام الإضافي | W9: حساب الإضافي | X9: إجمالي أيام العمل | Y9: راتب أيام العمل | Z9: السهرات | AA9: الأساسي | AC9: الراتب | AD9: الراتب + مكافأة | AE9: أيام الإضافي | AF9: حساب الإضافي | AG9: إجمالي أيام العمل | AH9: راتب أيام العمل | AI9: السهرات | AJ9: الأساسي
B10: =SUM(G10:H10) -> 3967.5 | C10: =SUM(B10+I10) -> 5692.5 | D10: =SUM(C16:I16,C23:I23,C30:I30,C37:I37,C44:I44,C51:I51) -> 39 | E10: =SUM(D10*E4) -> 2242.5 | F10: =SUM(D10+30) -> 69 | G10: =SUM(I10+E10) -> 3967.5 | H10: =SUM(C17:I17,C24:I24,C31:I31,C38:I38,C45:I45,C52:I52)*20 -> 0 | I10: =SUM(G2) -> 1725 | K10: =SUM(P10:Q10) -> 3967.5 | L10: =SUM(K10+R10) -> 5692.5 | M10: =SUM(L16:R16,L23:R23,L30:R30,L37:R37,L44:R44,L51:R51) -> 39 | N10: =SUM(M10*N4) -> 2242.5 | O10: =SUM(M10+30) -> 69 | P10: =SUM(R10+N10) -> 3967.5 | Q10: =SUM(L17:R17,L24:R24,L31:R31,L38:R38,L45:R45,L52:R52)*20 -> 0 | R10: =SUM(P2) -> 1725 | T10: =SUM(Y10:Z10) -> 3795 | U10: =SUM(T10+AA10) -> 5520 | V10: =SUM(U16:AA16,U23:AA23,U30:AA30,U37:AA37,U44:AA44,U51:AA51) -> 36 | W10: =SUM(V10*W4) -> 2070 | X10: =SUM(V10+30) -> 66 | Y10: =SUM(AA10+W10) -> 3795 | Z10: =SUM(U17:AA17,U24:AA24,U31:AA31,U38:AA38,U45:AA45,U52:AA52)*20 -> 0 | AA10: =SUM(Y2) -> 1725 | AC10: =SUM(AH10:AI10) -> 4082.5 | AD10: =SUM(AC10+AJ10) -> 5807.5 | AE10: =SUM(AD16:AJ16,AD23:AJ23,AD30:AJ30,AD37:AJ37,AD44:AJ44,AD51:AJ51) -> 41 | AF10: =SUM(AE10*AF4) -> 2357.5 | AG10: =SUM(AE10+30) -> 71 | AH10: =SUM(AJ10+AF10) -> 4082.5 | AI10: =SUM(AD17:AJ17,AD24:AJ24,AD31:AJ31,AD38:AJ38,AD45:AJ45,AD52:AJ52)*20 -> 0 | AJ10: =SUM(AH2) -> 1725
C12: السبت | D12: الأحد | E12: الاثنين | F12: الثلاثاء | G12: الأربعاء | H12: الخميس | I12: الجمعة | L12: السبت | M12: الأحد | N12: الاثنين | O12: الثلاثاء | P12: الأربعاء | Q12: الخميس | R12: الجمعة | U12: السبت | V12: الأحد | W12: الاثنين | X12: الثلاثاء | Y12: الأربعاء | Z12: الخميس | AA12: الجمعة | AD12: السبت | AE12: الأحد | AF12: الاثنين | AG12: الثلاثاء | AH12: الأربعاء | AI12: الخميس | AJ12: الجمعة
C13: 46018 | D13: 46019 | E13: 46020 | F13: 46021 | G13: 46022 | H13: 46023 | I13: 46024 | O13: 46049 | P13: 46050 | Q13: 46051 | R13: 46052 | AA13: 46080 | AJ13: 46108
B14: سبب أجازة | K14: سبب أجازة | T14: سبب أجازة | AC14: سبب أجازة
B15: أجازات | K15: أجازات | T15: أجازات | AC15: أجازات
B16: إضافي | C16: 1 | D16: 1 | E16: 1 | F16: 1 | G16: 1 | H16: 1 | I16: 3 | K16: إضافي | O16: 1 | P16: 1 | Q16: 1 | R16: 3 | T16: إضافي | AA16: 3 | AC16: إضافي | AJ16: 3
B17: سهرات | K17: سهرات | T17: سهرات | AC17: سهرات
C19: السبت | D19: الأحد | E19: الاثنين | F19: الثلاثاء | G19: الأربعاء | H19: الخميس | I19: الجمعة | L19: السبت | M19: الأحد | N19: الاثنين | O19: الثلاثاء | P19: الأربعاء | Q19: الخميس | R19: الجمعة | U19: السبت | V19: الأحد | W19: الاثنين | X19: الثلاثاء | Y19: الأربعاء | Z19: الخميس | AA19: الجمعة | AD19: السبت | AE19: الأحد | AF19: الاثنين | AG19: الثلاثاء | AH19: الأربعاء | AI19: الخميس | AJ19: الجمعة
C20: 46025 | D20: 46026 | E20: 46027 | F20: 46028 | G20: 46029 | H20: 46030 | I20: 46031 | L20: 46053 | M20: 46054 | N20: 46055 | O20: 46056 | P20: 46057 | Q20: 46058 | R20: 46059 | U20: 46081 | V20: 46082 | W20: 46083 | X20: 46084 | Y20: 46085 | Z20: 46086 | AA20: 46087 | AD20: 46109 | AE20: 46110 | AF20: 46111 | AG20: 46112 | AH20: 46113 | AI20: 46114 | AJ20: 46115
B21: سبب أجازة | K21: سبب أجازة | T21: سبب أجازة | AC21: سبب أجازة
B22: أجازات | K22: أجازات | T22: أجازات | AC22: أجازات
B23: إضافي | C23: 1 | D23: 1 | E23: 1 | F23: 1 | G23: 1 | H23: 1 | I23: 3 | K23: إضافي | L23: 1 | M23: 1 | N23: 1 | O23: 1 | P23: 1 | Q23: 1 | R23: 3 | T23: إضافي | U23: 1 | V23: 1 | W23: 1 | X23: 1 | Y23: 1 | Z23: 1 | AA23: 3 | AC23: إضافي | AD23: 1 | AE23: 1 | AF23: 1 | AG23: 1 | AH23: 1 | AI23: 1 | AJ23: 3
B24: سهرات | K24: سهرات | T24: سهرات | AC24: سهرات
C26: السبت | D26: الأحد | E26: الاثنين | F26: الثلاثاء | G26: الأربعاء | H26: الخميس | I26: الجمعة | L26: السبت | M26: الأحد | N26: الاثنين | O26: الثلاثاء | P26: الأربعاء | Q26: الخميس | R26: الجمعة | U26: السبت | V26: الأحد | W26: الاثنين | X26: الثلاثاء | Y26: الأربعاء | Z26: الخميس | AA26: الجمعة | AD26: السبت | AE26: الأحد | AF26: الاثنين | AG26: الثلاثاء | AH26: الأربعاء | AI26: الخميس | AJ26: الجمعة
C27: 46032 | D27: 46033 | E27: 46034 | F27: 46035 | G27: 46036 | H27: 46037 | I27: 46038 | L27: 46060 | M27: 46061 | N27: 46062 | O27: 46063 | P27: 46064 | Q27: 46065 | R27: 46066 | U27: 46088 | V27: 46089 | W27: 46090 | X27: 46091 | Y27: 46092 | Z27: 46093 | AA27: 46094 | AD27: 46116 | AE27: 46117 | AF27: 46118 | AG27: 46119 | AH27: 46120 | AI27: 46121 | AJ27: 46122
B28: سبب أجازة | K28: سبب أجازة | T28: سبب أجازة | AC28: سبب أجازة
B29: أجازات | K29: أجازات | T29: أجازات | AC29: أجازات
B30: إضافي | C30: 1 | D30: 1 | E30: 1 | F30: 1 | G30: 1 | H30: 1 | I30: 3 | K30: إضافي | L30: 1 | M30: 1 | N30: 1 | O30: 1 | P30: 1 | Q30: 1 | R30: 3 | T30: إضافي | U30: 1 | V30: 1 | W30: 1 | X30: 1 | Y30: 1 | Z30: 1 | AA30: 3 | AC30: إضافي | AD30: 1 | AE30: 1 | AF30: 1 | AG30: 1 | AH30: 1 | AI30: 1 | AJ30: 3
B31: سهرات | K31: سهرات | T31: سهرات | AC31: سهرات
C33: السبت | D33: الأحد | E33: الاثنين | F33: الثلاثاء | G33: الأربعاء | H33: الخميس | I33: الجمعة | L33: السبت | M33: الأحد | N33: الاثنين | O33: الثلاثاء | P33: الأربعاء | Q33: الخميس | R33: الجمعة | U33: السبت | V33: الأحد | W33: الاثنين | X33: الثلاثاء | Y33: الأربعاء | Z33: الخميس | AA33: الجمعة | AD33: السبت | AE33: الأحد | AF33: الاثنين | AG33: الثلاثاء | AH33: الأربعاء | AI33: الخميس | AJ33: الجمعة
C34: 46039 | D34: 46040 | E34: 46041 | F34: 46042 | G34: 46043 | H34: 46044 | I34: 46045 | L34: 46067 | M34: 46068 | N34: 46069 | O34: 46070 | P34: 46071 | Q34: 46072 | R34: 46073 | U34: 46095 | V34: 46096 | W34: 46097 | X34: 46098 | Y34: 46099 | Z34: 46100 | AA34: 46101 | AD34: 46123 | AE34: 46124 | AF34: 46125 | AG34: 46126 | AH34: 46127 | AI34: 46128 | AJ34: 46129
B35: سبب أجازة | K35: سبب أجازة | T35: سبب أجازة | AC35: سبب أجازة
B36: أجازات | K36: أجازات | T36: أجازات | AC36: أجازات
B37: إضافي | C37: 1 | D37: 1 | E37: 1 | F37: 1 | G37: 1 | H37: 1 | I37: 3 | K37: إضافي | L37: 1 | M37: 1 | N37: 1 | O37: 1 | P37: 1 | Q37: 1 | R37: 3 | T37: إضافي | U37: 1 | V37: 1 | W37: 1 | X37: 1 | Y37: 1 | Z37: 1 | AA37: 3 | AC37: إضافي | AD37: 1 | AE37: 1 | AF37: 1 | AG37: 1 | AH37: 1 | AI37: 1 | AJ37: 3
B38: سهرات | K38: سهرات | T38: سهرات | AC38: سهرات
C40: السبت | D40: الأحد | E40: الاثنين | F40: الثلاثاء | G40: الأربعاء | H40: الخميس | I40: الجمعة | L40: السبت | M40: الأحد | N40: الاثنين | O40: الثلاثاء | P40: الأربعاء | Q40: الخميس | R40: الجمعة | U40: السبت | V40: الأحد | W40: الاثنين | X40: الثلاثاء | Y40: الأربعاء | Z40: الخميس | AA40: الجمعة | AD40: السبت | AE40: الأحد | AF40: الاثنين | AG40: الثلاثاء | AH40: الأربعاء | AI40: الخميس | AJ40: الجمعة
C41: 46046 | D41: 46047 | E41: 46048 | L41: 46074 | M41: 46075 | N41: 46076 | O41: 46077 | P41: 46078 | Q41: 46079 | U41: 46102 | V41: 46103 | W41: 46104 | X41: 46105 | Y41: 46106 | Z41: 46107 | AD41: 46130 | AE41: 46131 | AF41: 46132 | AG41: 46133 | AH41: 46134 | AI41: 46135 | AJ41: 46136
B42: سبب أجازة | K42: سبب أجازة | T42: سبب أجازة | AC42: سبب أجازة
B43: أجازات | K43: أجازات | T43: أجازات | AC43: أجازات
B44: إضافي | C44: 1 | D44: 1 | E44: 1 | K44: إضافي | L44: 1 | M44: 1 | N44: 1 | O44: 1 | P44: 1 | Q44: 1 | T44: إضافي | U44: 1 | V44: 1 | W44: 1 | X44: 1 | Y44: 1 | Z44: 1 | AC44: إضافي | AD44: 1 | AE44: 1 | AF44: 1 | AG44: 1 | AH44: 1 | AI44: 1 | AJ44: 3
B45: سهرات | K45: سهرات | T45: سهرات | AC45: سهرات
C47: السبت | D47: الأحد | E47: الاثنين | F47: الثلاثاء | G47: الأربعاء | H47: الخميس | I47: الجمعة | L47: السبت | M47: الأحد | N47: الاثنين | O47: الثلاثاء | P47: الأربعاء | Q47: الخميس | R47: الجمعة | U47: السبت | V47: الأحد | W47: الاثنين | X47: الثلاثاء | Y47: الأربعاء | Z47: الخميس | AA47: الجمعة | AD47: السبت | AE47: الأحد | AF47: الاثنين | AG47: الثلاثاء | AH47: الأربعاء | AI47: الخميس | AJ47: الجمعة
L48: 46074 | M48: 46075 | N48: 46076 | O48: 46077 | P48: 46078 | Q48: 46079 | U48: 46102 | V48: 46103 | W48: 46104 | X48: 46105 | Y48: 46106 | Z48: 46107 | AD48: 46137 | AE48: 46138
B49: سبب أجازة | K49: سبب أجازة | T49: سبب أجازة | AC49: سبب أجازة
...

Sheet 1
J2: شهر يناير 2026
M9: أيام الحضور | P9: أساسي قديم | S9: أساسي حالي | V9: فئة اليوم
M12: =SUM(AI39:AI40) -> 71 | P12: 2576.61 | S12: =SUM(P12*1) -> 2576.61 | V12: =SUM(S12/30) -> 85.887
J15: الاجازات | Y15: باقي الاجازات
P16: الراتب | S16: الراتب + مكافأة
J18: =SUM(AI37+'2'!AI36+'3'!AI36+'4'!AI36+'5'!AI36+'6'!AI36+'7'!AI36+'8'!AI36+'9'!AI36+'10'!AI36+'11'!AI36+'12'!AI36) -> 0 | Y18: =SUM(30-J18) -> 30
P19: =(M12*V12)+AI41 -> 6097.977 | S19: =SUM(P19+S12) -> 8674.587
P23: سلفيات
P26: 1000
P30: الراتب | S30: الراتب + مكافأة
P33: =SUM(P19-P26) -> 5097.977 | S33: =SUM(S19-P26) -> 7674.587
AI37: =SUM(C37:AG37) -> 0 | AJ37: الأجازات
B38: Day | C38: 27 | D38: 28 | E38: 29 | F38: 30 | G38: 31 | H38: 1 | I38: 2 | J38: 3 | K38: 4 | L38: 5 | M38: 6 | N38: 7 | O38: 8 | P38: 9 | Q38: 10 | R38: 11 | S38: 12 | T38: 13 | U38: 14 | V38: 15 | W38: 16 | X38: 17 | Y38: 18 | Z38: 19 | AA38: 20 | AB38: 21 | AC38: 22 | AD38: 23 | AE38: 24 | AF38: 25 | AG38: 26
B39: Presence-Till-2 | C39: 1 | D39: 1 | E39: 1 | F39: 1 | G39: 0 | H39: 1 | I39: 1 | J39: 1 | K39: 1 | L39: 1 | M39: 1 | N39: 1 | O39: 1 | P39: 1 | Q39: 1 | R39: 1 | S39: 1 | T39: 1 | U39: 1 | V39: 1 | W39: 1 | X39: 1 | Y39: 1 | Z39: 1 | AA39: 1 | AB39: 1 | AC39: 1 | AD39: 1 | AE39: 1 | AF39: 1 | AG39: 1 | AI39: =SUM(C39:AG39) -> 30 | AJ39: الأساسي
B40: Presence-From-2:6 | C40: 1 | D40: 1 | E40: 1 | F40: 1 | G40: 1 | H40: 1 | I40: 3 | J40: 1 | K40: 1 | L40: 1 | M40: 1 | N40: 1 | O40: 2 | P40: 3 | Q40: 1 | R40: 1 | S40: 1 | T40: 1 | U40: 1 | V40: 1 | W40: 3 | X40: 1 | Y40: 1 | Z40: 1 | AA40: 1 | AB40: 1 | AC40: 1 | AD40: 3 | AE40: 2 | AF40: 1 | AG40: 1 | AI40: =SUM(C40:AG40) -> 41 | AJ40: الأضافي
AI41: =SUM(C41:AG41) -> 0 | AJ41: السهرات

Sheet 2
J2: شهر فبراير 2026
M8: أيام الحضور | P8: أساسي | V8: فئة اليوم
M11: =SUM(AI38:AI39) -> 69 | P11: =SUM('1'!S12:U14) -> 2576.61 | V11: =SUM(P11/30) -> 85.887
J14: الاجازات | Y14: باقي الاجازات
P15: الراتب | S15: الراتب + مكافأة
J17: =SUM('1'!AI37+'2'!AI36+'3'!AI36+'4'!AI36+'5'!AI36+'6'!AI36+'7'!AI36+'8'!AI36+'9'!AI36+'10'!AI36+'11'!AI36+'12'!AI36) -> 0 | Y17: =SUM(30-J17) -> 30
P18: =(M11*V11)+AI40 -> 5926.203 | S18: =SUM(P18+P11) -> 8502.813
P22: سلفيات
P25: 1000
P29: الراتب | S29: الراتب + مكافأة
P32: =SUM(P18-P25) -> 4926.203 | S32: =SUM(S18-P25) -> 7502.813
AI36: =SUM(C36:AG36) -> 0 | AJ36: الأجازات
B37: Day | C37: 27 | D37: 28 | E37: 29 | F37: 30 | G37: 31 | H37: 1 | I37: 2 | J37: 3 | K37: 4 | L37: 5 | M37: 6 | N37: 7 | O37: 8 | P37: 9 | Q37: 10 | R37: 11 | S37: 12 | T37: 13 | U37: 14 | V37: 15 | W37: 16 | X37: 17 | Y37: 18 | Z37: 19 | AA37: 20 | AB37: 21 | AC37: 22 | AD37: 23 | AE37: 24 | AF37: 25 | AG37: 26
B38: Presence-Till-2 | C38: 1 | D38: 1 | E38: 1 | F38: 1 | G38: 0 | H38: 1 | I38: 1 | J38: 1 | K38: 1 | L38: 1 | M38: 1 | N38: 1 | O38: 1 | P38: 1 | Q38: 1 | R38: 1 | S38: 1 | T38: 1 | U38: 1 | V38: 1 | W38: 1 | X38: 1 | Y38: 1 | Z38: 1 | AA38: 1 | AB38: 1 | AC38: 1 | AD38: 1 | AE38: 1 | AF38: 1 | AG38: 1 | AI38: =SUM(C38:AG38) -> 30 | AJ38: الأساسي
B39: Presence-From-2:6 | C39: 1 | D39: 1 | E39: 1 | F39: 3 | G39: 1 | H39: 1 | I39: 1 | J39: 1 | K39: 1 | L39: 1 | M39: 3 | N39: 1 | O39: 1 | P39: 1 | Q39: 1 | R39: 1 | S39: 1 | T39: 3 | U39: 1 | V39: 1 | W39: 1 | X39: 1 | Y39: 1 | Z39: 1 | AA39: 3 | AB39: 1 | AC39: 1 | AD39: 1 | AE39: 1 | AF39: 1 | AG39: 1 | AI39: =SUM(C39:AG39) -> 39 | AJ39: الأضافي
AI40: =SUM(C40:AG40) -> 0 | AJ40: السهرات

Sheet 3
J2: شهر مارس 2026
M8: أيام الحضور | P8: أساسي | V8: فئة اليوم
M11: =SUM(AI38:AI39) -> 63 | P11: =SUM('1'!S12:U14) -> 2576.61 | V11: =SUM(P11/30) -> 85.887
J14: الاجازات | Y14: باقي الاجازات
P15: الراتب | S15: الراتب + مكافأة
J17: =SUM('1'!AI37+'2'!AI36+'3'!AI36+'4'!AI36+'5'!AI36+'6'!AI36+'7'!AI36+'8'!AI36+'9'!AI36+'10'!AI36+'11'!AI36+'12'!AI36) -> 0 | Y17: =SUM(30-J17) -> 30
P18: =(M11*V11)+AI40 -> 5410.881 | S18: =SUM(P18+P11) -> 7987.491
P22: سلفيات
P25: 1000
P29: الراتب | S29: الراتب + مكافأة
P32: =SUM(P18-P25) -> 4410.881 | S32: =SUM(S18-P25) -> 6987.491
AI36: =SUM(C36:AG36) -> 0 | AJ36: الأجازات
B37: Day | C37: 27 | D37: 28 | E37: 29 | F37: 30 | G37: 31 | H37: 1 | I37: 2 | J37: 3 | K37: 4 | L37: 5 | M37: 6 | N37: 7 | O37: 8 | P37: 9 | Q37: 10 | R37: 11 | S37: 12 | T37: 13 | U37: 14 | V37: 15 | W37: 16 | X37: 17 | Y37: 18 | Z37: 19 | AA37: 20 | AB37: 21 | AC37: 22 | AD37: 23 | AE37: 24 | AF37: 25 | AG37: 26
B38: Presence-Till-2 | C38: 1 | D38: 1 | E38: 1 | F38: 1 | G38: 0 | H38: 1 | I38: 1 | J38: 1 | K38: 1 | L38: 1 | M38: 1 | N38: 1 | O38: 1 | P38: 1 | Q38: 1 | R38: 1 | S38: 1 | T38: 1 | U38: 1 | V38: 1 | W38: 1 | X38: 1 | Y38: 1 | Z38: 1 | AA38: 1 | AB38: 1 | AC38: 1 | AD38: 1 | AE38: 1 | AF38: 1 | AG38: 1 | AI38: =SUM(C38:AG38) -> 30 | AJ38: الأساسي
B39: Presence-From-2:6 | C39: 3 | D39: 1 | E39: 0 | F39: 0 | G39: 0 | H39: 1 | I39: 1 | J39: 1 | K39: 1 | L39: 1 | M39: 3 | N39: 1 | O39: 1 | P39: 1 | Q39: 1 | R39: 1 | S39: 1 | T39: 3 | U39: 1 | V39: 1 | W39: 1 | X39: 1 | Y39: 1 | Z39: 1 | AA39: 3 | AB39: 0 | AC39: 0 | AD39: 0 | AE39: 1 | AF39: 1 | AG39: 1 | AI39: =SUM(C39:AG39) -> 33 | AJ39: الأضافي
AI40: =SUM(C40:AG40) -> 0 | AJ40: السهرات

Sheet 4
J2: شهر أبريل 2026
M8: أيام الحضور | P8: أساسي | V8: فئة اليوم
M11: =SUM(AI38:AI39) -> 73 | P11: =SUM('1'!S12:U14) -> 2576.61 | V11: =SUM(P11/30) -> 85.887
J14: الاجازات | Y14: باقي الاجازات
P15: الراتب | S15: الراتب + مكافأة
J17: =SUM('1'!AI37+'2'!AI36+'3'!AI36+'4'!AI36+'5'!AI36+'6'!AI36+'7'!AI36+'8'!AI36+'9'!AI36+'10'!AI36+'11'!AI36+'12'!AI36) -> 0 | Y17: =SUM(30-J17) -> 30
P18: =(M11*V11)+AI40 -> 6269.751 | S18: =SUM(P18+P11) -> 8846.361
P22: سلفيات
P25: 1000
P29: الراتب | S29: الراتب + مكافأة
P32: =SUM(P18-P25) -> 5269.751 | S32: =SUM(S18-P25) -> 7846.361
AI36: =SUM(C36:AG36) -> 0 | AJ36: الأجازات
B37: Day | C37: 27 | D37: 28 | E37: 29 | F37: 30 | G37: 31 | H37: 1 | I37: 2 | J37: 3 | K37: 4 | L37: 5 | M37: 6 | N37: 7 | O37: 8 | P37: 9 | Q37: 10 | R37: 11 | S37: 12 | T37: 13 | U37: 14 | V37: 15 | W37: 16 | X37: 17 | Y37: 18 | Z37: 19 | AA37: 20 | AB37: 21 | AC37: 22 | AD37: 23 | AE37: 24 | AF37: 25 | AG37: 26
B38: Presence-Till-2 | C38: 1 | D38: 1 | E38: 1 | F38: 1 | G38: 0 | H38: 1 | I38: 1 | J38: 1 | K38: 1 | L38: 1 | M38: 1 | N38: 1 | O38: 1 | P38: 1 | Q38: 1 | R38: 1 | S38: 1 | T38: 1 | U38: 1 | V38: 1 | W38: 1 | X38: 1 | Y38: 1 | Z38: 1 | AA38: 1 | AB38: 1 | AC38: 1 | AD38: 1 | AE38: 1 | AF38: 1 | AG38: 1 | AI38: =SUM(C38:AG38) -> 30 | AJ38: الأساسي
B39: Presence-From-2:6 | C39: 3 | D39: 1 | E39: 1 | F39: 1 | G39: 1 | H39: 1 | I39: 1 | J39: 3 | K39: 1 | L39: 1 | M39: 1 | N39: 1 | O39: 1 | P39: 1 | Q39: 3 | R39: 1 | S39: 1 | T39: 2 | U39: 1 | V39: 1 | W39: 1 | X39: 3 | Y39: 1 | Z39: 1 | AA39: 1 | AB39: 1 | AC39: 1 | AD39: 1 | AE39: 3 | AF39: 2 | AG39: 1 | AI39: =SUM(C39:AG39) -> 43 | AJ39: الأضافي
AI40: =SUM(C40:AG40) -> 0 | AJ40: السهرات

Sheet 5
J2: شهرمايو 2026
M8: أيام الحضور | P8: أساسي | V8: فئة اليوم
M11: =SUM(AI38:AI39) -> 68 | P11: =SUM('1'!S12:U14) -> 2576.61 | V11: =SUM(P11/30) -> 85.887
J14: الاجازات | Y14: باقي الاجازات
P15: الراتب | S15: الراتب + مكافأة
J17: =SUM('1'!AI37+'2'!AI36+'3'!AI36+'4'!AI36+'5'!AI36+'6'!AI36+'7'!AI36+'8'!AI36+'9'!AI36+'10'!AI36+'11'!AI36+'12'!AI36) -> 0 | Y17: =SUM(30-J17) -> 30
P18: =(M11*V11)+AI40 -> 5840.316 | S18: =SUM(P18+P11) -> 8416.926
P22: سلفيات
P25: 1000
P29: الراتب | S29: الراتب + مكافأة
P32: =SUM(P18-P25) -> 4840.316 | S32: =SUM(S18-P25) -> 7416.926
AI36: =SUM(C36:AG36) -> 0 | AJ36: الأجازات
B37: Day | C37: 27 | D37: 28 | E37: 29 | F37: 30 | G37: 31 | H37: 1 | I37: 2 | J37: 3 | K37: 4 | L37: 5 | M37: 6 | N37: 7 | O37: 8 | P37: 9 | Q37: 10 | R37: 11 | S37: 12 | T37: 13 | U37: 14 | V37: 15 | W37: 16 | X37: 17 | Y37: 18 | Z37: 19 | AA37: 20 | AB37: 21 | AC37: 22 | AD37: 23 | AE37: 24 | AF37: 25 | AG37: 26
B38: Presence-Till-2 | C38: 1 | D38: 1 | E38: 1 | F38: 1 | G38: 0 | H38: 1 | I38: 1 | J38: 1 | K38: 1 | L38: 1 | M38: 1 | N38: 1 | O38: 1 | P38: 1 | Q38: 1 | R38: 1 | S38: 1 | T38: 1 | U38: 1 | V38: 1 | W38: 1 | X38: 1 | Y38: 1 | Z38: 1 | AA38: 1 | AB38: 1 | AC38: 1 | AD38: 1 | AE38: 1 | AF38: 1 | AG38: 1 | AI38: =SUM(C38:AG38) -> 30 | AJ38: الأساسي
B39: Presence-From-2:6 | C39: 1 | D39: 1 | E39: 1 | F39: 1 | G39: 0 | H39: 3 | I39: 2 | J39: 1 | K39: 1 | L39: 1 | M39: 1 | N39: 1 | O39: 3 | P39: 1 | Q39: 1 | R39: 1 | S39: 1 | T39: 1 | U39: 1 | V39: 3 | W39: 1 | X39: 1 | Y39: 1 | Z39: 1 | AA39: 1 | AB39: 1 | AC39: 3 | AD39: 1 | AE39: 1 | AF39: 1 | AG39: 0 | AI39: =SUM(C39:AG39) -> 38 | AJ39: الأضافي
AI40: =SUM(C40:AG40) -> 0 | AJ40: السهرات

Sheet 6
J2: شهر يونيو 2026
M8: أيام الحضور | P8: أساسي | V8: فئة اليوم
M11: =SUM(AI38:AI39) -> 53 | P11: =SUM('1'!S12:U14) -> 2576.61 | V11: =SUM(P11/30) -> 85.887
J14: الاجازات | Y14: باقي الاجازات
P15: الراتب | S15: الراتب + مكافأة
J17: =SUM('1'!AI37+'2'!AI36+'3'!AI36+'4'!AI36+'5'!AI36+'6'!AI36+'7'!AI36+'8'!AI36+'9'!AI36+'10'!AI36+'11'!AI36+'12'!AI36) -> 0 | Y17: =SUM(30-J17) -> 30
P18: =(M11*V11)+AI40 -> 4552.011 | S18: =SUM(P18+P11) -> 7128.621
P22: سلفيات
P25: 1000
P29: الراتب | S29: الراتب + مكافأة
P32: =SUM(P18-P25) -> 3552.011 | S32: =SUM(S18-P25) -> 6128.621
AI36: =SUM(C36:AG36) -> 0 | AJ36: الأجازات
B37: Day | C37: 27 | D37: 28 | E37: 29 | F37: 30 | G37: 31 | H37: 1 | I37: 2 | J37: 3 | K37: 4 | L37: 5 | M37: 6 | N37: 7 | O37: 8 | P37: 9 | Q37: 10 | R37: 11 | S37: 12 | T37: 13 | U37: 14 | V37: 15 | W37: 16 | X37: 17 | Y37: 18 | Z37: 19 | AA37: 20 | AB37: 21 | AC37: 22 | AD37: 23 | AE37: 24 | AF37: 25 | AG37: 26
B38: Presence-Till-2 | C38: 1 | D38: 1 | E38: 1 | F38: 1 | G38: 0 | H38: 1 | I38: 1 | J38: 1 | K38: 1 | L38: 1 | M38: 1 | N38: 1 | O38: 1 | P38: 1 | Q38: 1 | R38: 1 | S38: 1 | T38: 1 | U38: 1 | V38: 1 | W38: 1 | X38: 1 | Y38: 1 | Z38: 1 | AA38: 1 | AB38: 1 | AC38: 1 | AD38: 1 | AE38: 1 | AF38: 1 | AG38: 1 | AI38: =SUM(C38:AG38) -> 30 | AJ38: الأساسي
B39: Presence-From-2:6 | C39: 0 | D39: 0 | E39: 0 | F39: 1 | G39: 1 | H39: 1 | I39: 1 | J39: 1 | K39: 1 | L39: 0 | M39: 1 | N39: 1 | O39: 1 | P39: 1 | Q39: 1 | R39: 1 | S39: 0 | T39: 1 | U39: 1 | V39: 1 | W39: 1 | X39: 0 | Y39: 1 | Z39: 0 | AA39: 1 | AB39: 1 | AC39: 1 | AD39: 1 | AE39: 1 | AF39: 1 | AG39: 0 | AI39: =SUM(C39:AG39) -> 23 | AJ39: الأضافي
AI40: =SUM(C40:AG40) -> 0 | AJ40: السهرات

Sheet 7
J2: شهر يوليو 2026
M8: أيام الحضور | P8: أساسي | V8: فئة اليوم
M11: =SUM(AI38:AI39) -> 52 | P11: =SUM('1'!S12:U14) -> 2576.61 | V11: =SUM(P11/30) -> 85.887
J14: الاجازات | Y14: باقي الاجازات
P15: الراتب | S15: الراتب + مكافأة
J17: =SUM('1'!AI37+'2'!AI36+'3'!AI36+'4'!AI36+'5'!AI36+'6'!AI36+'7'!AI36+'8'!AI36+'9'!AI36+'10'!AI36+'11'!AI36+'12'!AI36) -> 0 | Y17: =SUM(30-J17) -> 30
P18: =(M11*V11)+AI40 -> 4466.124 | S18: =SUM(P18+P11) -> 7042.734
P22: سلفيات
P25: 1000
P29: الراتب | S29: الراتب + مكافأة
P32: =SUM(P18-P25) -> 3466.124 | S32: =SUM(S18-P25) -> 6042.734
AI36: =SUM(C36:AG36) -> 0 | AJ36: الأجازات
B37: Day | C37: 27 | D37: 28 | E37: 29 | F37: 30 | G37: 31 | H37: 1 | I37: 2 | J37: 3 | K37: 4 | L37: 5 | M37: 6 | N37: 7 | O37: 8 | P37: 9 | Q37: 10 | R37: 11 | S37: 12 | T37: 13 | U37: 14 | V37: 15 | W37: 16 | X37: 17 | Y37: 18 | Z37: 19 | AA37: 20 | AB37: 21 | AC37: 22 | AD37: 23 | AE37: 24 | AF37: 25 | AG37: 26
B38: Presence-Till-2 | C38: 1 | D38: 1 | E38: 1 | F38: 1 | G38: 0 | H38: 1 | I38: 1 | J38: 1 | K38: 1 | L38: 1 | M38: 1 | N38: 1 | O38: 1 | P38: 1 | Q38: 1 | R38: 1 | S38: 1 | T38: 1 | U38: 1 | V38: 1 | W38: 1 | X38: 1 | Y38: 1 | Z38: 1 | AA38: 1 | AB38: 1 | AC38: 1 | AD38: 1 | AE38: 1 | AF38: 1 | AG38: 1 | AI38: =SUM(C38:AG38) -> 30 | AJ38: الأساسي
B39: Presence-From-2:6 | C39: 1 | D39: 1 | E39: 1 | F39: 1 | G39: 0 | H39: 1 | I39: 0 | J39: 0 | K39: 1 | L39: 1 | M39: 1 | N39: 1 | O39: 1 | P39: 0 | Q39: 0 | R39: 1 | S39: 1 | T39: 1 | U39: 1 | V39: 1 | W39: 0 | X39: 0 | Y39: 1 | Z39: 1 | AA39: 1 | AB39: 1 | AC39: 1 | AD39: 0 | AE39: 0 | AF39: 1 | AG39: 1 | AI39: =SUM(C39:AG39) -> 22 | AJ39: الأضافي
AI40: =SUM(C40:AG40) -> 0 | AJ40: السهرات

Sheet 8
J2: شهر أغسطس 2026
M8: أيام الحضور | P8: أساسي | V8: فئة اليوم
M11: =SUM(AI38:AI39) -> 57 | P11: =SUM('1'!S12:U14) -> 2576.61 | V11: =SUM(P11/30) -> 85.887
J14: الاجازات | Y14: باقي الاجازات
P15: الراتب | S15: الراتب + مكافأة
J17: =SUM('1'!AI37+'2'!AI36+'3'!AI36+'4'!AI36+'5'!AI36+'6'!AI36+'7'!AI36+'8'!AI36+'9'!AI36+'10'!AI36+'11'!AI36+'12'!AI36) -> 0 | Y17: =SUM(30-J17) -> 30
P18: =(M11*V11)+AI40 -> 4895.559 | S18: =SUM(P18+P11) -> 7472.169
P22: سلفيات
P25: 1000
P29: الراتب | S29: الراتب + مكافأة
P32: =SUM(P18-P25) -> 3895.559 | S32: =SUM(S18-P25) -> 6472.169
AI36: =SUM(C36:AG36) -> 0 | AJ36: الأجازات
B37: Day | C37: 27 | D37: 28 | E37: 29 | F37: 30 | G37: 31 | H37: 1 | I37: 2 | J37: 3 | K37: 4 | L37: 5 | M37: 6 | N37: 7 | O37: 8 | P37: 9 | Q37: 10 | R37: 11 | S37: 12 | T37: 13 | U37: 14 | V37: 15 | W37: 16 | X37: 17 | Y37: 18 | Z37: 19 | AA37: 20 | AB37: 21 | AC37: 22 | AD37: 23 | AE37: 24 | AF37: 25 | AG37: 26
B38: Presence-Till-2 | C38: 1 | D38: 1 | E38: 1 | F38: 1 | G38: 0 | H38: 1 | I38: 1 | J38: 1 | K38: 1 | L38: 1 | M38: 1 | N38: 1 | O38: 1 | P38: 1 | Q38: 1 | R38: 1 | S38: 1 | T38: 1 | U38: 1 | V38: 1 | W38: 1 | X38: 1 | Y38: 1 | Z38: 1 | AA38: 1 | AB38: 1 | AC38: 1 | AD38: 1 | AE38: 1 | AF38: 1 | AG38: 1 | AI38: =SUM(C38:AG38) -> 30 | AJ38: الأساسي
B39: Presence-From-2:6 | C39: 1 | D39: 1 | E39: 1 | F39: 1 | G39: 0 | H39: 1 | I39: 1 | J39: 1 | K39: 1 | L39: 1 | M39: 1 | N39: 0 | O39: 1 | P39: 1 | Q39: 1 | R39: 1 | S39: 1 | T39: 1 | U39: 0 | V39: 1 | W39: 1 | X39: 1 | Y39: 1 | Z39: 1 | AA39: 1 | AB39: 0 | AC39: 1 | AD39: 1 | AE39: 1 | AF39: 1 | AG39: 1 | AI39: =SUM(C39:AG39) -> 27 | AJ39: الأضافي
AI40: =SUM(C40:AG40) -> 0 | AJ40: السهرات

Sheet 9
J2: شهر سبتمبر 2026
M8: أيام الحضور | P8: أساسي | V8: فئة اليوم
M11: =SUM(AI38:AI39) -> 55 | P11: =SUM('1'!S12:U14) -> 2576.61 | V11: =SUM(P11/30) -> 85.887
J14: الاجازات | Y14: باقي الاجازات
P15: الراتب | S15: الراتب + مكافأة
J17: =SUM('1'!AI37+'2'!AI36+'3'!AI36+'4'!AI36+'5'!AI36+'6'!AI36+'7'!AI36+'8'!AI36+'9'!AI36+'10'!AI36+'11'!AI36+'12'!AI36) -> 0 | Y17: =SUM(30-J17) -> 30
P18: =(M11*V11)+AI40 -> 4723.785 | S18: =SUM(P18+P11) -> 7300.395
P22: سلفيات
P25: 1000
P29: الراتب | S29: الراتب + مكافأة
P32: =SUM(P18-P25) -> 3723.785 | S32: =SUM(S18-P25) -> 6300.395
AI36: =SUM(C36:AG36) -> 0 | AJ36: الأجازات
B37: Day | C37: 27 | D37: 28 | E37: 29 | F37: 30 | G37: 31 | H37: 1 | I37: 2 | J37: 3 | K37: 4 | L37: 5 | M37: 6 | N37: 7 | O37: 8 | P37: 9 | Q37: 10 | R37: 11 | S37: 12 | T37: 13 | U37: 14 | V37: 15 | W37: 16 | X37: 17 | Y37: 18 | Z37: 19 | AA37: 20 | AB37: 21 | AC37: 22 | AD37: 23 | AE37: 24 | AF37: 25 | AG37: 26
B38: Presence-Till-2 | C38: 1 | D38: 1 | E38: 1 | F38: 1 | G38: 0 | H38: 1 | I38: 1 | J38: 1 | K38: 1 | L38: 1 | M38: 1 | N38: 1 | O38: 1 | P38: 1 | Q38: 1 | R38: 1 | S38: 1 | T38: 1 | U38: 1 | V38: 1 | W38: 1 | X38: 1 | Y38: 1 | Z38: 1 | AA38: 1 | AB38: 1 | AC38: 1 | AD38: 1 | AE38: 1 | AF38: 1 | AG38: 1 | AI38: =SUM(C38:AG38) -> 30 | AJ38: الأساسي
B39: Presence-From-2:6 | C39: 0 | D39: 0 | E39: 1 | F39: 1 | G39: 1 | H39: 1 | I39: 1 | J39: 1 | K39: 0 | L39: 1 | M39: 1 | N39: 1 | O39: 1 | P39: 1 | Q39: 1 | R39: 0 | S39: 1 | T39: 1 | U39: 1 | V39: 1 | W39: 1 | X39: 1 | Y39: 0 | Z39: 1 | AA39: 1 | AB39: 1 | AC39: 1 | AD39: 1 | AE39: 1 | AF39: 0 | AG39: 1 | AI39: =SUM(C39:AG39) -> 25 | AJ39: الأضافي
AI40: =SUM(C40:AG40) -> 0 | AJ40: السهرات

Sheet 10
J2: شهر اكتوبر 2026
M8: أيام الحضور | P8: أساسي | V8: فئة اليوم
M11: =SUM(AI38:AI39) -> 55 | P11: =SUM('1'!S12:U14) -> 2576.61 | V11: =SUM(P11/30) -> 85.887
J14: الاجازات | Y14: باقي الاجازات
P15: الراتب | S15: الراتب + مكافأة
J17: =SUM('1'!AI37+'2'!AI36+'3'!AI36+'4'!AI36+'5'!AI36+'6'!AI36+'7'!AI36+'8'!AI36+'9'!AI36+'10'!AI36+'11'!AI36+'12'!AI36) -> 0 | Y17: =SUM(30-J17) -> 30
P18: =(M11*V11)+AI40 -> 4723.785 | S18: =SUM(P18+P11) -> 7300.395
P22: سلفيات
P25: 1000
P29: الراتب | S29: الراتب + مكافأة
P32: =SUM(P18-P25) -> 3723.785 | S32: =SUM(S18-P25) -> 6300.395
AI36: =SUM(C36:AG36) -> 0 | AJ36: الأجازات
B37: Day | C37: 27 | D37: 28 | E37: 29 | F37: 30 | G37: 31 | H37: 1 | I37: 2 | J37: 3 | K37: 4 | L37: 5 | M37: 6 | N37: 7 | O37: 8 | P37: 9 | Q37: 10 | R37: 11 | S37: 12 | T37: 13 | U37: 14 | V37: 15 | W37: 16 | X37: 17 | Y37: 18 | Z37: 19 | AA37: 20 | AB37: 21 | AC37: 22 | AD37: 23 | AE37: 24 | AF37: 25 | AG37: 26
B38: Presence-Till-2 | C38: 1 | D38: 1 | E38: 1 | F38: 1 | G38: 0 | H38: 1 | I38: 1 | J38: 1 | K38: 1 | L38: 1 | M38: 1 | N38: 1 | O38: 1 | P38: 1 | Q38: 1 | R38: 1 | S38: 1 | T38: 1 | U38: 1 | V38: 1 | W38: 1 | X38: 1 | Y38: 1 | Z38: 1 | AA38: 1 | AB38: 1 | AC38: 1 | AD38: 1 | AE38: 1 | AF38: 1 | AG38: 1 | AI38: =SUM(C38:AG38) -> 30 | AJ38: الأساسي
B39: Presence-From-2:6 | C39: 1 | D39: 1 | E39: 1 | F39: 1 | G39: 0 | H39: 1 | I39: 0 | J39: 1 | K39: 1 | L39: 1 | M39: 1 | N39: 1 | O39: 0 | P39: 0 | Q39: 1 | R39: 1 | S39: 1 | T39: 1 | U39: 1 | V39: 1 | W39: 0 | X39: 1 | Y39: 1 | Z39: 1 | AA39: 1 | AB39: 1 | AC39: 1 | AD39: 0 | AE39: 1 | AF39: 1 | AG39: 1 | AI39: =SUM(C39:AG39) -> 25 | AJ39: الأضافي
AI40: =SUM(C40:AG40) -> 0 | AJ40: السهرات

Sheet 11
J2: شهر نوفمبر 2026
M8: أيام الحضور | P8: أساسي | V8: فئة اليوم
M11: =SUM(AI38:AI39) -> 57 | P11: =SUM('1'!S12:U14) -> 2576.61 | V11: =SUM(P11/30) -> 85.887
J14: الاجازات | Y14: باقي الاجازات
P15: الراتب | S15: الراتب + مكافأة
J17: =SUM('1'!AI37+'2'!AI36+'3'!AI36+'4'!AI36+'5'!AI36+'6'!AI36+'7'!AI36+'8'!AI36+'9'!AI36+'10'!AI36+'11'!AI36+'12'!AI36) -> 0 | Y17: =SUM(30-J17) -> 30
P18: =(M11*V11)+AI40 -> 4895.559 | S18: =SUM(P18+P11) -> 7472.169
P22: سلفيات
P25: 1000
P29: الراتب | S29: الراتب + مكافأة
P32: =SUM(P18-P25) -> 3895.559 | S32: =SUM(S18-P25) -> 6472.169
AI36: =SUM(C36:AG36) -> 0 | AJ36: الأجازات
B37: Day | C37: 27 | D37: 28 | E37: 29 | F37: 30 | G37: 31 | H37: 1 | I37: 2 | J37: 3 | K37: 4 | L37: 5 | M37: 6 | N37: 7 | O37: 8 | P37: 9 | Q37: 10 | R37: 11 | S37: 12 | T37: 13 | U37: 14 | V37: 15 | W37: 16 | X37: 17 | Y37: 18 | Z37: 19 | AA37: 20 | AB37: 21 | AC37: 22 | AD37: 23 | AE37: 24 | AF37: 25 | AG37: 26
B38: Presence-Till-2 | C38: 1 | D38: 1 | E38: 1 | F38: 1 | G38: 0 | H38: 1 | I38: 1 | J38: 1 | K38: 1 | L38: 1 | M38: 1 | N38: 1 | O38: 1 | P38: 1 | Q38: 1 | R38: 1 | S38: 1 | T38: 1 | U38: 1 | V38: 1 | W38: 1 | X38: 1 | Y38: 1 | Z38: 1 | AA38: 1 | AB38: 1 | AC38: 1 | AD38: 1 | AE38: 1 | AF38: 1 | AG38: 1 | AI38: =SUM(C38:AG38) -> 30 | AJ38: الأساسي
B39: Presence-From-2:6 | C39: 1 | D39: 1 | E39: 1 | F39: 0 | G39: 1 | H39: 1 | I39: 1 | J39: 1 | K39: 1 | L39: 1 | M39: 0 | N39: 1 | O39: 1 | P39: 1 | Q39: 1 | R39: 1 | S39: 1 | T39: 0 | U39: 1 | V39: 1 | W39: 1 | X39: 1 | Y39: 1 | Z39: 1 | AA39: 0 | AB39: 1 | AC39: 1 | AD39: 1 | AE39: 1 | AF39: 1 | AG39: 1 | AI39: =SUM(C39:AG39) -> 27 | AJ39: الأضافي
AI40: =SUM(C40:AG40) -> 0 | AJ40: السهرات

Sheet 12
J2: شهر ديسمبر 2026
M8: أيام الحضور | P8: أساسي | V8: فئة اليوم
M11: =SUM(AI38:AI39) -> 70 | P11: =SUM('1'!S12:U14) -> 2576.61 | V11: =SUM(P11/30) -> 85.887
J14: الاجازات | Y14: باقي الاجازات
P15: الراتب | S15: الراتب + مكافأة
J17: =SUM('1'!AI37+'2'!AI36+'3'!AI36+'4'!AI36+'5'!AI36+'6'!AI36+'7'!AI36+'8'!AI36+'9'!AI36+'10'!AI36+'11'!AI36+'12'!AI36) -> 0 | Y17: =SUM(30-J17) -> 30
P18: =(M11*V11)+AI40 -> 6012.09 | S18: =SUM(P18+P11) -> 8588.7
P22: سلفيات
P25: 1000
P29: الراتب | S29: الراتب + مكافأة
P32: =SUM(P18-P25) -> 5012.09 | S32: =SUM(S18-P25) -> 7588.7
AI36: =SUM(C36:AG36) -> 0 | AJ36: الأجازات
B37: Day | C37: 27 | D37: 28 | E37: 29 | F37: 30 | G37: 31 | H37: 1 | I37: 2 | J37: 3 | K37: 4 | L37: 5 | M37: 6 | N37: 7 | O37: 8 | P37: 9 | Q37: 10 | R37: 11 | S37: 12 | T37: 13 | U37: 14 | V37: 15 | W37: 16 | X37: 17 | Y37: 18 | Z37: 19 | AA37: 20 | AB37: 21 | AC37: 22 | AD37: 23 | AE37: 24 | AF37: 25 | AG37: 26
B38: Presence-Till-2 | C38: 1 | D38: 1 | E38: 1 | F38: 1 | G38: 0 | H38: 1 | I38: 1 | J38: 1 | K38: 1 | L38: 1 | M38: 1 | N38: 1 | O38: 1 | P38: 1 | Q38: 1 | R38: 1 | S38: 1 | T38: 1 | U38: 1 | V38: 1 | W38: 1 | X38: 1 | Y38: 1 | Z38: 1 | AA38: 1 | AB38: 1 | AC38: 1 | AD38: 1 | AE38: 1 | AF38: 1 | AG38: 1 | AI38: =SUM(C38:AG38) -> 30 | AJ38: الأساسي
B39: Presence-From-2:6 | C39: 3 | D39: 1 | E39: 1 | F39: 1 | G39: 0 | H39: 1 | I39: 1 | J39: 1 | K39: 3 | L39: 1 | M39: 1 | N39: 1 | O39: 1 | P39: 1 | Q39: 1 | R39: 3 | S39: 1 | T39: 1 | U39: 1 | V39: 1 | W39: 1 | X39: 1 | Y39: 3 | Z39: 1 | AA39: 1 | AB39: 1 | AC39: 1 | AD39: 1 | AE39: 1 | AF39: 3 | AG39: 1 | AI39: =SUM(C39:AG39) -> 40 | AJ39: الأضافي
AI40: =SUM(C40:AG40) -> 0 | AJ40: السهرات
